Workbook

Sheet Industry_Skillset
A1: S.No | B1: Skill | C1: Added Frequency | D1: Skill Percentage | E1: CSV Files Represented (Out of 13) | F1: Batch / CSV File Names | G1: Skill Category
A2: 1 | B2: Python | C2: 117 | D2: =(C2/130)*100 -> 90 | E2: 13 | F2: JD(1-10)_TOP25(2).csv, JD(11-20)_TOP25(2).csv, JD(21-30)_TOP25(2).csv, JD(31-40)_TOP25(2).csv, JD(41-50)_TOP25(2).csv, JD(51-60)_TOP25(2).csv, JD(61-70)_TOP25(2).csv, JD(71-80)_TOP25(2).csv, JD(81-90)_TOP25(2).csv, JD(91-100)_TOP25(2).csv, JD(101-111)_TOP25(2).csv, JD(112-120)_TOP25(2).csv, JD(121-130)_TOP25(2).csv | G2: Programming Languages
A3: 2 | B3: Communication & Collaboration | C3: 110 | D3: =(C3/130)*100 -> 84.615385 | E3: 12 | F3: JD(1-10)_TOP25(2).csv, JD(11-20)_TOP25(2).csv, JD(21-30)_TOP25(2).csv, JD(31-40)_TOP25(2).csv, JD(41-50)_TOP25(2).csv, JD(51-60)_TOP25(2).csv, JD(61-70)_TOP25(2).csv, JD(71-80)_TOP25(2).csv, JD(81-90)_TOP25(2).csv, JD(91-100)_TOP25(2).csv, JD(112-120)_TOP25(2).csv, JD(121-130)_TOP25(2).csv | G3: Professional & Soft Skills
A4: 3 | B4: Machine Learning | C4: 107 | D4: =(C4/130)*100 -> 82.307692 | E4: 13 | F4: JD(1-10)_TOP25(2).csv, JD(11-20)_TOP25(2).csv, JD(21-30)_TOP25(2).csv, JD(31-40)_TOP25(2).csv, JD(41-50)_TOP25(2).csv, JD(51-60)_TOP25(2).csv, JD(61-70)_TOP25(2).csv, JD(71-80)_TOP25(2).csv, JD(81-90)_TOP25(2).csv, JD(91-100)_TOP25(2).csv, JD(101-111)_TOP25(2).csv, JD(112-120)_TOP25(2).csv, JD(121-130)_TOP25(2).csv | G4: Machine Learning
A5: 4 | B5: Analytical Thinking & Problem Solving | C5: 100 | D5: =(C5/130)*100 -> 76.923077 | E5: 12 | F5: JD(1-10)_TOP25(2).csv, JD(11-20)_TOP25(2).csv, JD(21-30)_TOP25(2).csv, JD(31-40)_TOP25(2).csv, JD(41-50)_TOP25(2).csv, JD(51-60)_TOP25(2).csv, JD(71-80)_TOP25(2).csv, JD(81-90)_TOP25(2).csv, JD(91-100)_TOP25(2).csv, JD(112-120)_TOP25(2).csv, JD(121-130)_TOP25(2).csv, JD(101-111)_TOP25(2).csv | G5: Professional & Soft Skills
A6: 5 | B6: SQL | C6: 69 | D6: =(C6/130)*100 -> 53.076923 | E6: 13 | F6: JD(1-10)_TOP25(2).csv, JD(11-20)_TOP25(2).csv, JD(21-30)_TOP25(2).csv, JD(31-40)_TOP25(2).csv, JD(41-50)_TOP25(2).csv, JD(51-60)_TOP25(2).csv, JD(61-70)_TOP25(2).csv, JD(71-80)_TOP25(2).csv, JD(81-90)_TOP25(2).csv, JD(91-100)_TOP25(2).csv, JD(101-111)_TOP25(2).csv, JD(112-120)_TOP25(2).csv, JD(121-130)_TOP25(2).csv | G6: Databases & SQL
A7: 6 | B7: Cloud Platforms (AWS / Azure / GCP) | C7: 63 | D7: =(C7/130)*100 -> 48.461538 | E7: 13 | F7: JD(1-10)_TOP25(2).csv, JD(11-20)_TOP25(2).csv, JD(21-30)_TOP25(2).csv, JD(31-40)_TOP25(2).csv, JD(41-50)_TOP25(2).csv, JD(51-60)_TOP25(2).csv, JD(61-70)_TOP25(2).csv, JD(71-80)_TOP25(2).csv, JD(81-90)_TOP25(2).csv, JD(91-100)_TOP25(2).csv, JD(112-120)_TOP25(2).csv, JD(121-130)_TOP25(2).csv, JD(101-111)_TOP25(2).csv | G7: Cloud & MLOps
A8: 7 | B8: Scikit-learn / NumPy / Pandas | C8: 62 | D8: =(C8/130)*100 -> 47.692308 | E8: 12 | F8: JD(1-10)_TOP25(2).csv, JD(11-20)_TOP25(2).csv, JD(31-40)_TOP25(2).csv, JD(41-50)_TOP25(2).csv, JD(51-60)_TOP25(2).csv, JD(61-70)_TOP25(2).csv, JD(71-80)_TOP25(2).csv, JD(101-111)_TOP25(2).csv, JD(121-130)_TOP25(2).csv, JD(21-30)_TOP25(2).csv, JD(81-90)_TOP25(2).csv, JD(91-100)_TOP25(2).csv | G8: Machine Learning
A9: 8 | B9: Statistical Analysis | C9: 62 | D9: =(C9/130)*100 -> 47.692308 | E9: 10 | F9: JD(1-10)_TOP25(2).csv, JD(11-20)_TOP25(2).csv, JD(21-30)_TOP25(2).csv, JD(31-40)_TOP25(2).csv, JD(41-50)_TOP25(2).csv, JD(51-60)_TOP25(2).csv, JD(61-70)_TOP25(2).csv, JD(81-90)_TOP25(2).csv, JD(91-100)_TOP25(2).csv, JD(101-111)_TOP25(2).csv | G9: Data Analysis & Statistics
A10: 9 | B10: Large Language Models (LLMs) | C10: 48 | D10: =(C10/130)*100 -> 36.923077 | E10: 11 | F10: JD(1-10)_TOP25(2).csv, JD(11-20)_TOP25(2).csv, JD(21-30)_TOP25(2).csv, JD(41-50)_TOP25(2).csv, JD(61-70)_TOP25(2).csv, JD(71-80)_TOP25(2).csv, JD(81-90)_TOP25(2).csv, JD(91-100)_TOP25(2).csv, JD(101-111)_TOP25(2).csv, JD(112-120)_TOP25(2).csv, JD(121-130)_TOP25(2).csv | G10: Generative AI & NLP
A11: 10 | B11: Generative AI | C11: 45 | D11: =(C11/130)*100 -> 34.615385 | E11: 10 | F11: JD(1-10)_TOP25(2).csv, JD(11-20)_TOP25(2).csv, JD(41-50)_TOP25(2).csv, JD(51-60)_TOP25(2).csv, JD(61-70)_TOP25(2).csv, JD(71-80)_TOP25(2).csv, JD(81-90)_TOP25(2).csv, JD(91-100)_TOP25(2).csv, JD(112-120)_TOP25(2).csv, JD(121-130)_TOP25(2).csv | G11: Generative AI & NLP
A12: 11 | B12: PyTorch | C12: 44 | D12: =(C12/130)*100 -> 33.846154 | E12: 11 | F12: JD(1-10)_TOP25(2).csv, JD(11-20)_TOP25(2).csv, JD(21-30)_TOP25(2).csv, JD(31-40)_TOP25(2).csv, JD(41-50)_TOP25(2).csv, JD(51-60)_TOP25(2).csv, JD(61-70)_TOP25(2).csv, JD(71-80)_TOP25(2).csv, JD(81-90)_TOP25(2).csv, JD(101-111)_TOP25(2).csv, JD(121-130)_TOP25(2).csv | G12: Deep Learning
A13: 12 | B13: TensorFlow / Keras | C13: 42 | D13: =(C13/130)*100 -> 32.307692 | E13: 10 | F13: JD(101-111)_TOP25(2).csv, JD(1-10)_TOP25(2).csv, JD(11-20)_TOP25(2).csv, JD(31-40)_TOP25(2).csv, JD(41-50)_TOP25(2).csv, JD(51-60)_TOP25(2).csv, JD(61-70)_TOP25(2).csv, JD(71-80)_TOP25(2).csv, JD(81-90)_TOP25(2).csv, JD(121-130)_TOP25(2).csv | G13: Deep Learning
... A82: 81 | B82: Browser Automation | C82: 1 | D82: =(C82/130)*100 -> 0.76923077 | E82: 1 | F82: JD(112-120)_TOP25(2).csv | G82: Software Engineering

Sheet Curriculum_Skillset
A1: S.No | B1: Skill | C1: Added Frequency | D1: Skill Percentage | E1: CSV Files Represented (Out of 16) | F1: CSV Files Mentioning | G1: Skill Category
A2: 1 | B2: Statistics | C2: 80 | D2: =(C2/80)*100 -> 100 | E2: 16 | F2: CSVU1.csv, CSVU10.csv, CSVU11.csv, CSVU12.csv, CSVU13.csv, CSVU14.csv, CSVU15.csv, CSVU16.csv, CSVU2.csv, CSVU3.csv, CSVU4.csv, CSVU5.csv, CSVU6.csv, CSVU7.csv, CSVU8.csv, CSVU9.csv | G2: Data Analysis & Statistics
A3: 2 | B3: Python | C3: 79 | D3: =(C3/80)*100 -> 98.75 | E3: 16 | F3: CSVU1.csv, CSVU10.csv, CSVU11.csv, CSVU12.csv, CSVU13.csv, CSVU14.csv, CSVU15.csv, CSVU16.csv, CSVU2.csv, CSVU3.csv, CSVU4.csv, CSVU5.csv, CSVU6.csv, CSVU7.csv, CSVU8.csv, CSVU9.csv | G3: Programming Languages
A4: 3 | B4: Machine Learning | C4: 75 | D4: =(C4/80)*100 -> 93.75 | E4: 16 | F4: CSVU1.csv, CSVU10.csv, CSVU11.csv, CSVU12.csv, CSVU13.csv, CSVU14.csv, CSVU15.csv, CSVU16.csv, CSVU2.csv, CSVU3.csv, CSVU4.csv, CSVU5.csv, CSVU6.csv, CSVU7.csv, CSVU8.csv, CSVU9.csv | G4: Machine Learning
A5: 4 | B5: Data Structures | C5: 72 | D5: =(C5/80)*100 -> 90 | E5: 15 | F5: CSVU10.csv, CSVU11.csv, CSVU12.csv, CSVU13.csv, CSVU14.csv, CSVU15.csv, CSVU16.csv, CSVU2.csv, CSVU3.csv, CSVU4.csv, CSVU5.csv, CSVU6.csv, CSVU7.csv, CSVU8.csv, CSVU9.csv | G5: Software Engineering
A6: 5 | B6: Deep Learning | C6: 63 | D6: =(C6/80)*100 -> 78.75 | E6: 15 | F6: CSVU1.csv, CSVU10.csv, CSVU12.csv, CSVU13.csv, CSVU14.csv, CSVU15.csv, CSVU16.csv, CSVU2.csv, CSVU3.csv, CSVU4.csv, CSVU5.csv, CSVU6.csv, CSVU7.csv, CSVU8.csv, CSVU9.csv | G6: Deep Learning
A7: 6 | B7: Data Mining | C7: 61 | D7: =(C7/80)*100 -> 76.25 | E7: 15 | F7: CSVU10.csv, CSVU11.csv, CSVU12.csv, CSVU13.csv, CSVU14.csv, CSVU15.csv, CSVU16.csv, CSVU2.csv, CSVU3.csv, CSVU4.csv, CSVU5.csv, CSVU6.csv, CSVU7.csv, CSVU8.csv, CSVU9.csv | G7: Data Analysis & Statistics
A8: 7 | B8: Artificial Intelligence | C8: 61 | D8: =(C8/80)*100 -> 76.25 | E8: 14 | F8: CSVU1.csv, CSVU11.csv, CSVU12.csv, CSVU13.csv, CSVU14.csv, CSVU15.csv, CSVU16.csv, CSVU2.csv, CSVU3.csv, CSVU4.csv, CSVU5.csv, CSVU6.csv, CSVU7.csv, CSVU9.csv | G8: Artificial Intelligence
A9: 8 | B9: Probability | C9: 61 | D9: =(C9/80)*100 -> 76.25 | E9: 13 | F9: CSVU1.csv, CSVU10.csv, CSVU12.csv, CSVU13.csv, CSVU14.csv, CSVU15.csv, CSVU16.csv, CSVU3.csv, CSVU4.csv, CSVU6.csv, CSVU7.csv, CSVU8.csv, CSVU9.csv | G9: Data Analysis & Statistics
A10: 9 | B10: Natural Language Processing | C10: 56 | D10: =(C10/80)*100 -> 70 | E10: 14 | F10: CSVU10.csv, CSVU11.csv, CSVU12.csv, CSVU13.csv, CSVU14.csv, CSVU15.csv, CSVU16.csv, CSVU2.csv, CSVU3.csv, CSVU4.csv, CSVU5.csv, CSVU7.csv, CSVU8.csv, CSVU9.csv | G10: Generative AI & NLP
A11: 10 | B11: Data Analytics | C11: 56 | D11: =(C11/80)*100 -> 70 | E11: 12 | F11: CSVU1.csv, CSVU10.csv, CSVU11.csv, CSVU12.csv, CSVU14.csv, CSVU2.csv, CSVU3.csv, CSVU5.csv, CSVU6.csv, CSVU7.csv, CSVU8.csv, CSVU9.csv | G11: Data Analysis & Statistics
A12: 11 | B12: Database Management Systems | C12: 49 | D12: =(C12/80)*100 -> 61.25 | E12: 11 | F12: CSVU1.csv, CSVU10.csv, CSVU11.csv, CSVU13.csv, CSVU15.csv, CSVU16.csv, CSVU4.csv, CSVU5.csv, CSVU6.csv, CSVU7.csv, CSVU8.csv | G12: Databases & SQL
A13: 12 | B13: Cloud Computing | C13: 46 | D13: =(C13/80)*100 -> 57.5 | E13: 12 | F13: CSVU1.csv, CSVU10.csv, CSVU11.csv, CSVU13.csv, CSVU15.csv, CSVU16.csv, CSVU2.csv, CSVU3.csv, CSVU4.csv, CSVU6.csv, CSVU8.csv, CSVU9.csv | G13: Cloud & MLOps
... A80: 79 | B80: Social Network Analysis | C80: 2 | D80: =(C80/80)*100 -> 2.5 | E80: 1 | F80: CSVU16.csv | G80: Domain Applications

Sheet Skill Frequency Analysis
A1: Analysis 1
A2: SKILL FREQUENCY ANALYSIS
A5: INDUSTRY SKILL FREQUENCY | J5: CURRICULUM SKILL FREQUENCY
A6: Rank | B6: Skill | C6: Added Frequency | E6: Skill Prevalence | J6: Rank | K6: Skill | L6: Added Frequency | N6: Skill Prevalence
A7: =_xlfn.RANK.EQ(C7,$C$7:$C$99,0) -> 1 | B7: =Industry_Skillset!B2 -> Python | C7: =Industry_Skillset!C2 -> 117 | E7: =C7/130 -> 0.9 | J7: =_xlfn.RANK.EQ(L7,$L$7:$L$90,0) -> 1 | K7: =Curriculum_Skillset!B2 -> Statistics | L7: =Curriculum_Skillset!C2 -> 80 | N7: =L7/80 -> 1
A8: =_xlfn.RANK.EQ(C8,$C$7:$C$99,0) -> 2 | B8: =Industry_Skillset!B3 -> Communication & Collaboration | C8: =Industry_Skillset!C3 -> 110 | E8: =C8/130 -> 0.84615385 | J8: =_xlfn.RANK.EQ(L8,$L$7:$L$90,0) -> 2 | K8: =Curriculum_Skillset!B3 -> Python | L8: =Curriculum_Skillset!C3 -> 79 | N8: =L8/80 -> 0.9875
A9: =_xlfn.RANK.EQ(C9,$C$7:$C$99,0) -> 3 | B9: =Industry_Skillset!B4 -> Machine Learning | C9: =Industry_Skillset!C4 -> 107 | E9: =C9/130 -> 0.82307692 | J9: =_xlfn.RANK.EQ(L9,$L$7:$L$90,0) -> 3 | K9: =Curriculum_Skillset!B4 -> Machine Learning | L9: =Curriculum_Skillset!C4 -> 75 | N9: =L9/80 -> 0.9375
A10: =_xlfn.RANK.EQ(C10,$C$7:$C$99,0) -> 4 | B10: =Industry_Skillset!B5 -> Analytical Thinking & Problem Solving | C10: =Industry_Skillset!C5 -> 100 | E10: =C10/130 -> 0.76923077 | J10: =_xlfn.RANK.EQ(L10,$L$7:$L$90,0) -> 4 | K10: =Curriculum_Skillset!B5 -> Data Structures | L10: =Curriculum_Skillset!C5 -> 72 | N10: =L10/80 -> 0.9
A11: =_xlfn.RANK.EQ(C11,$C$7:$C$99,0) -> 5 | B11: =Industry_Skillset!B6 -> SQL | C11: =Industry_Skillset!C6 -> 69 | E11: =C11/130 -> 0.53076923 | J11: =_xlfn.RANK.EQ(L11,$L$7:$L$90,0) -> 5 | K11: =Curriculum_Skillset!B6 -> Deep Learning | L11: =Curriculum_Skillset!C6 -> 63 | N11: =L11/80 -> 0.7875
A12: =_xlfn.RANK.EQ(C12,$C$7:$C$99,0) -> 6 | B12: =Industry_Skillset!B7 -> Cloud Platforms (AWS / Azure / GCP) | C12: =Industry_Skillset!C7 -> 63 | E12: =C12/130 -> 0.48461538 | J12: =_xlfn.RANK.EQ(L12,$L$7:$L$90,0) -> 6 | K12: =Curriculum_Skillset!B7 -> Data Mining | L12: =Curriculum_Skillset!C7 -> 61 | N12: =L12/80 -> 0.7625
A13: =_xlfn.RANK.EQ(C13,$C$7:$C$99,0) -> 7 | B13: =Industry_Skillset!B8 -> Scikit-learn / NumPy / Pandas | C13: =Industry_Skillset!C8 -> 62 | E13: =C13/130 -> 0.47692308 | J13: =_xlfn.RANK.EQ(L13,$L$7:$L$90,0) -> 6 | K13: =Curriculum_Skillset!B8 -> Artificial Intelligence | L13: =Curriculum_Skillset!C8 -> 61 | N13: =L13/80 -> 0.7625
A14: =_xlfn.RANK.EQ(C14,$C$7:$C$99,0) -> 7 | B14: =Industry_Skillset!B9 -> Statistical Analysis | C14: =Industry_Skillset!C9 -> 62 | E14: =C14/130 -> 0.47692308 | J14: =_xlfn.RANK.EQ(L14,$L$7:$L$90,0) -> 6 | K14: =Curriculum_Skillset!B9 -> Probability | L14: =Curriculum_Skillset!C9 -> 61 | N14: =L14/80 -> 0.7625
A15: =_xlfn.RANK.EQ(C15,$C$7:$C$99,0) -> 9 | B15: =Industry_Skillset!B10 -> Large Language Models (LLMs) | C15: =Industry_Skillset!C10 -> 48 | E15: =C15/130 -> 0.36923077 | J15: =_xlfn.RANK.EQ(L15,$L$7:$L$90,0) -> 9 | K15: =Curriculum_Skillset!B10 -> Natural Language Processing | L15: =Curriculum_Skillset!C10 -> 56 | N15: =L15/80 -> 0.7
A16: =_xlfn.RANK.EQ(C16,$C$7:$C$99,0) -> 10 | B16: =Industry_Skillset!B11 -> Generative AI | C16: =Industry_Skillset!C11 -> 45 | E16: =C16/130 -> 0.34615385 | J16: =_xlfn.RANK.EQ(L16,$L$7:$L$90,0) -> 9 | K16: =Curriculum_Skillset!B11 -> Data Analytics | L16: =Curriculum_Skillset!C11 -> 56 | N16: =L16/80 -> 0.7
A17: =_xlfn.RANK.EQ(C17,$C$7:$C$99,0) -> 11 | B17: =Industry_Skillset!B12 -> PyTorch | C17: =Industry_Skillset!C12 -> 44 | E17: =C17/130 -> 0.33846154 | J17: =_xlfn.RANK.EQ(L17,$L$7:$L$90,0) -> 11 | K17: =Curriculum_Skillset!B12 -> Database Management Systems | L17: =Curriculum_Skillset!C12 -> 49 | N17: =L17/80 -> 0.6125
A18: =_xlfn.RANK.EQ(C18,$C$7:$C$99,0) -> 12 | B18: =Industry_Skillset!B13 -> TensorFlow / Keras | C18: =Industry_Skillset!C13 -> 42 | E18: =C18/130 -> 0.32307692 | J18: =_xlfn.RANK.EQ(L18,$L$7:$L$90,0) -> 12 | K18: =Curriculum_Skillset!B13 -> Cloud Computing | L18: =Curriculum_Skillset!C13 -> 46 | N18: =L18/80 -> 0.575
... A85: =_xlfn.RANK.EQ(C85,$C$7:$C$99,0) -> 79 | B85: =Industry_Skillset!B80 -> AI Safety & Responsible AI | C85: =Industry_Skillset!C80 -> 1 | E85: =C85/130 -> 0.0076923077 | J85: =_xlfn.RANK.EQ(L85,$L$7:$L$90,0) -> 77 | K85: =Curriculum_Skillset!B80 -> Social Network Analysis | L85: =Curriculum_Skillset!C80 -> 2 | N85: =L85/80 -> 0.025
A86: =_xlfn.RANK.EQ(C86,$C$7:$C$99,0) -> 79 | B86: =Industry_Skillset!B81 -> Autonomous Driving / ADAS | C86: =Industry_Skillset!C81 -> 1 | E86: =C86/130 -> 0.0076923077
A87: =_xlfn.RANK.EQ(C87,$C$7:$C$99,0) -> 79 | B87: =Industry_Skillset!B82 -> Browser Automation | C87: =Industry_Skillset!C82 -> 1 | E87: =C87/130 -> 0.0076923077
B100: Metric | C100: Industry | D100: Curriculum
B101: Total Skills | C101: =COUNTA(B7:B99) -> 81 | D101: =COUNTA(K7:K90) -> 79
B102: Total Documents | C102: 130 | D102: 80
B103: Highest Frequency | C103: =MAX(C7:C99) -> 117 | D103: =MAX(L7:L90) -> 80
B104: Highest Prevalence | C104: =MAX(E7:E99) -> 0.9 | D104: =MAX(N7:N90) -> 1

Sheet Category Frequency Analysis 
A1: Analysis 2
A2: CATEGORY FREQUENCY ANALYSIS
A5: Industry Category Analysis | M5: Curriculum Category Analysis | X5: Skill Category | Z5: Industry | AA5: Curriculum
A6: Rank | B6: Skill Category | D6: Category Frequency | F6: Category Contribution (%) | M6: Rank | N6: Skill Category | P6: Category Frequency | R6: Category Contribution (%) | X6: Artificial Intelligence | Z6: =_xlfn.XLOOKUP(X6,$B$7:$B$20,$F$7:$F$20,"") -> 0.0035236082 | AA6: =_xlfn.XLOOKUP(X6,$N$7:$N$20,$R$7:$R$20,"") -> 0.049641148
A7: =_xlfn.RANK.EQ(D7,$D$7:$D$23,0) -> 2 | B7: Generative AI & NLP | D7: =SUMIF(Industry_Skillset!$G:$G,B7,Industry_Skillset!$C:$C) -> 222 | F7: =D7/$D$24 -> 0.1564482 | M7: =_xlfn.RANK.EQ(P7,$P$7:$P$23,0) -> 1 | N7: Data Analysis & Statistics | P7: =SUMIF(Curriculum_Skillset!$G$2:$G$81,N7,Curriculum_Skillset!$C$2:$C$81) -> 429 | R7: =P7/$P$24 -> 0.25657895 | X7: Cloud & MLOps | Z7: =_xlfn.XLOOKUP(X7,$B$7:$B$20,$F$7:$F$20,"") -> 0.093023256 | AA7: =_xlfn.XLOOKUP(X7,$N$7:$N$20,$R$7:$R$20,"") -> 0.035287081
A8: =_xlfn.RANK.EQ(D8,$D$7:$D$23,0) -> 3 | B8: Professional & Soft Skills | D8: =SUMIF(Industry_Skillset!$G:$G,B8,Industry_Skillset!$C:$C) -> 220 | F8: =D8/$D$24 -> 0.15503876 | M8: =_xlfn.RANK.EQ(P8,$P$7:$P$23,0) -> 2 | N8: Software Engineering | P8: =SUMIF(Curriculum_Skillset!$G$2:$G$81,N8,Curriculum_Skillset!$C$2:$C$81) -> 251 | R8: =P8/$P$24 -> 0.15011962 | X8: Computer Vision | Z8: =_xlfn.XLOOKUP(X8,$B$7:$B$20,$F$7:$F$20,"") -> 0.0028188865 | AA8: =_xlfn.XLOOKUP(X8,$N$7:$N$20,$R$7:$R$20,"") -> 0.0215311
A9: =_xlfn.RANK.EQ(D9,$D$7:$D$23,0) -> 1 | B9: Machine Learning | D9: =SUMIF(Industry_Skillset!$G:$G,B9,Industry_Skillset!$C:$C) -> 227 | F9: =D9/$D$24 -> 0.15997181 | M9: =_xlfn.RANK.EQ(P9,$P$7:$P$23,0) -> 3 | N9: Machine Learning | P9: =SUMIF(Curriculum_Skillset!$G$2:$G$81,N9,Curriculum_Skillset!$C$2:$C$81) -> 172 | R9: =P9/$P$24 -> 0.10287081 | X9: Data Analysis & Statistics | Z9: =_xlfn.XLOOKUP(X9,$B$7:$B$20,$F$7:$F$20,"") -> 0.10711769 | AA9: =_xlfn.XLOOKUP(X9,$N$7:$N$20,$R$7:$R$20,"") -> 0.25657895
A10: =_xlfn.RANK.EQ(D10,$D$7:$D$23,0) -> 4 | B10: Data Analysis & Statistics | D10: =SUMIF(Industry_Skillset!$G:$G,B10,Industry_Skillset!$C:$C) -> 152 | F10: =D10/$D$24 -> 0.10711769 | M10: =_xlfn.RANK.EQ(P10,$P$7:$P$23,0) -> 4 | N10: Programming Languages | P10: =SUMIF(Curriculum_Skillset!$G$2:$G$81,N10,Curriculum_Skillset!$C$2:$C$81) -> 144 | R10: =P10/$P$24 -> 0.086124402 | X10: Data Engineering & Big Data | Z10: =_xlfn.XLOOKUP(X10,$B$7:$B$20,$F$7:$F$20,"") -> 0.024665257 | AA10: =_xlfn.XLOOKUP(X10,$N$7:$N$20,$R$7:$R$20,"") -> 0.066985646
A11: =_xlfn.RANK.EQ(D11,$D$7:$D$23,0) -> 6 | B11: Programming Languages | D11: =SUMIF(Industry_Skillset!$G:$G,B11,Industry_Skillset!$C:$C) -> 129 | F11: =D11/$D$24 -> 0.090909091 | M11: =_xlfn.RANK.EQ(P11,$P$7:$P$23,0) -> 5 | N11: Data Engineering & Big Data | P11: =SUMIF(Curriculum_Skillset!$G$2:$G$81,N11,Curriculum_Skillset!$C$2:$C$81) -> 112 | R11: =P11/$P$24 -> 0.066985646 | X11: Data Visualization & BI | Z11: =_xlfn.XLOOKUP(X11,$B$7:$B$20,$F$7:$F$20,"") -> 0.040169133 | AA11: =_xlfn.XLOOKUP(X11,$N$7:$N$20,$R$7:$R$20,"") -> 0.042464115
A12: =_xlfn.RANK.EQ(D12,$D$7:$D$23,0) -> 5 | B12: Cloud & MLOps | D12: =SUMIF(Industry_Skillset!$G:$G,B12,Industry_Skillset!$C:$C) -> 132 | F12: =D12/$D$24 -> 0.093023256 | M12: =_xlfn.RANK.EQ(P12,$P$7:$P$23,0) -> 6 | N12: Databases & SQL | P12: =SUMIF(Curriculum_Skillset!$G$2:$G$81,N12,Curriculum_Skillset!$C$2:$C$81) -> 91 | R12: =P12/$P$24 -> 0.054425837 | X12: Databases & SQL | Z12: =_xlfn.XLOOKUP(X12,$B$7:$B$20,$F$7:$F$20,"") -> 0.052854123 | AA12: =_xlfn.XLOOKUP(X12,$N$7:$N$20,$R$7:$R$20,"") -> 0.054425837
A13: =_xlfn.RANK.EQ(D13,$D$7:$D$23,0) -> 7 | B13: Deep Learning | D13: =SUMIF(Industry_Skillset!$G:$G,B13,Industry_Skillset!$C:$C) -> 124 | F13: =D13/$D$24 -> 0.087385483 | M13: =_xlfn.RANK.EQ(P13,$P$7:$P$23,0) -> 7 | N13: Deep Learning | P13: =SUMIF(Curriculum_Skillset!$G$2:$G$81,N13,Curriculum_Skillset!$C$2:$C$81) -> 89 | R13: =P13/$P$24 -> 0.053229665 | X13: Deep Learning | Z13: =_xlfn.XLOOKUP(X13,$B$7:$B$20,$F$7:$F$20,"") -> 0.087385483 | AA13: =_xlfn.XLOOKUP(X13,$N$7:$N$20,$R$7:$R$20,"") -> 0.053229665
A14: =_xlfn.RANK.EQ(D14,$D$7:$D$23,0) -> 8 | B14: Databases & SQL | D14: =SUMIF(Industry_Skillset!$G:$G,B14,Industry_Skillset!$C:$C) -> 75 | F14: =D14/$D$24 -> 0.052854123 | M14: =_xlfn.RANK.EQ(P14,$P$7:$P$23,0) -> 8 | N14: Artificial Intelligence | P14: =SUMIF(Curriculum_Skillset!$G$2:$G$81,N14,Curriculum_Skillset!$C$2:$C$81) -> 83 | R14: =P14/$P$24 -> 0.049641148 | X14: Domain Applications | Z14: =_xlfn.XLOOKUP(X14,$B$7:$B$20,$F$7:$F$20,"") -> 0.007751938 | AA14: =_xlfn.XLOOKUP(X14,$N$7:$N$20,$R$7:$R$20,"") -> 0.032894737
A15: =_xlfn.RANK.EQ(D15,$D$7:$D$23,0) -> 9 | B15: Data Visualization & BI | D15: =SUMIF(Industry_Skillset!$G:$G,B15,Industry_Skillset!$C:$C) -> 57 | F15: =D15/$D$24 -> 0.040169133 | M15: =_xlfn.RANK.EQ(P15,$P$7:$P$23,0) -> 9 | N15: Generative AI & NLP | P15: =SUMIF(Curriculum_Skillset!$G$2:$G$81,N15,Curriculum_Skillset!$C$2:$C$81) -> 71 | R15: =P15/$P$24 -> 0.042464115 | X15: Generative AI & NLP | Z15: =_xlfn.XLOOKUP(X15,$B$7:$B$20,$F$7:$F$20,"") -> 0.1564482 | AA15: =_xlfn.XLOOKUP(X15,$N$7:$N$20,$R$7:$R$20,"") -> 0.042464115
A16: =_xlfn.RANK.EQ(D16,$D$7:$D$23,0) -> 10 | B16: Data Engineering & Big Data | D16: =SUMIF(Industry_Skillset!$G:$G,B16,Industry_Skillset!$C:$C) -> 35 | F16: =D16/$D$24 -> 0.024665257 | M16: =_xlfn.RANK.EQ(P16,$P$7:$P$23,0) -> 9 | N16: Data Visualization & BI | P16: =SUMIF(Curriculum_Skillset!$G$2:$G$81,N16,Curriculum_Skillset!$C$2:$C$81) -> 71 | R16: =P16/$P$24 -> 0.042464115 | X16: Machine Learning | Z16: =_xlfn.XLOOKUP(X16,$B$7:$B$20,$F$7:$F$20,"") -> 0.15997181 | AA16: =_xlfn.XLOOKUP(X16,$N$7:$N$20,$R$7:$R$20,"") -> 0.10287081
A17: =_xlfn.RANK.EQ(D17,$D$7:$D$23,0) -> 11 | B17: Software Engineering | D17: =SUMIF(Industry_Skillset!$G:$G,B17,Industry_Skillset!$C:$C) -> 26 | F17: =D17/$D$24 -> 0.018322763 | M17: =_xlfn.RANK.EQ(P17,$P$7:$P$23,0) -> 11 | N17: Cloud & MLOps | P17: =SUMIF(Curriculum_Skillset!$G$2:$G$81,N17,Curriculum_Skillset!$C$2:$C$81) -> 59 | R17: =P17/$P$24 -> 0.035287081 | X17: Professional & Soft Skills | Z17: =_xlfn.XLOOKUP(X17,$B$7:$B$20,$F$7:$F$20,"") -> 0.15503876 | AA17: =_xlfn.XLOOKUP(X17,$N$7:$N$20,$R$7:$R$20,"") -> 0.0053827751
A18: =_xlfn.RANK.EQ(D18,$D$7:$D$23,0) -> 12 | B18: Domain Applications | D18: =SUMIF(Industry_Skillset!$G:$G,B18,Industry_Skillset!$C:$C) -> 11 | F18: =D18/$D$24 -> 0.007751938 | M18: =_xlfn.RANK.EQ(P18,$P$7:$P$23,0) -> 12 | N18: Domain Applications | P18: =SUMIF(Curriculum_Skillset!$G$2:$G$81,N18,Curriculum_Skillset!$C$2:$C$81) -> 55 | R18: =P18/$P$24 -> 0.032894737 | X18: Programming Languages | Z18: =_xlfn.XLOOKUP(X18,$B$7:$B$20,$F$7:$F$20,"") -> 0.090909091 | AA18: =_xlfn.XLOOKUP(X18,$N$7:$N$20,$R$7:$R$20,"") -> 0.086124402
A19: =_xlfn.RANK.EQ(D19,$D$7:$D$23,0) -> 13 | B19: Artificial Intelligence | D19: =SUMIF(Industry_Skillset!$G:$G,B19,Industry_Skillset!$C:$C) -> 5 | F19: =D19/$D$24 -> 0.0035236082 | M19: =_xlfn.RANK.EQ(P19,$P$7:$P$23,0) -> 13 | N19: Computer Vision | P19: =SUMIF(Curriculum_Skillset!$G$2:$G$81,N19,Curriculum_Skillset!$C$2:$C$81) -> 36 | R19: =P19/$P$24 -> 0.0215311 | X19: Software Engineering | Z19: =_xlfn.XLOOKUP(X19,$B$7:$B$20,$F$7:$F$20,"") -> 0.018322763 | AA19: =_xlfn.XLOOKUP(X19,$N$7:$N$20,$R$7:$R$20,"") -> 0.15011962
A20: =_xlfn.RANK.EQ(D20,$D$7:$D$23,0) -> 14 | B20: Computer Vision | D20: =SUMIF(Industry_Skillset!$G:$G,B20,Industry_Skillset!$C:$C) -> 4 | F20: =D20/$D$24 -> 0.0028188865 | M20: =_xlfn.RANK.EQ(P20,$P$7:$P$23,0) -> 14 | N20: Professional & Soft Skills | P20: =SUMIF(Curriculum_Skillset!$G$2:$G$81,N20,Curriculum_Skillset!$C$2:$C$81) -> 9 | R20: =P20/$P$24 -> 0.0053827751
C24: Total | D24: =SUM(D7:D23) -> 1419 | O24: Total | P24: =SUM(P7:P23) -> 1672
B29: Metric | C29: Industry | D29: Curriculum
B30: Total Categories | C30: =COUNTA(B7:B23) -> 14 | D30: =COUNTA(N7:N23) -> 14
B31: Total Category Frequency | C31: =D24 -> 1419 | D31: =P24 -> 1672
B32: Highest Category Frequency | C32: =MAX(D7:D23) -> 227 | D32: =MAX(P7:P23) -> 429
B33: Highest Contribution (%) | C33: =MAX(F7:F23) -> 0.15997181 | D33: =MAX(R7:R23) -> 0.25657895

Sheet Skill_Matching
A1: Standardized Skill | B1: Industry Skill | C1: Industry Added Frequency | D1: Industry Prevalence | E1: Curriculum Skill | F1: Curriculum Added Frequency | G1: Curriculum Prevalence | H1: Match Status | I1: Matching Basis | J1: Industry Category | K1: Curriculum Category
A2: Python | B2: Python | C2: 117 | D2: 90 | E2: Python | F2: 79 | G2: 98.75 | H2: Covered | I2: Exact | J2: Programming Languages | K2: Programming Languages
A3: Communication & Collaboration | B3: Communication & Collaboration | C3: 110 | D3: 84.62 | H3: Industry Only | I3: No Match | J3: Professional & Soft Skills
A4: Machine Learning | B4: Machine Learning | C4: 107 | D4: 82.31 | E4: Machine Learning | F4: 75 | G4: 93.75 | H4: Covered | I4: Exact | J4: Machine Learning | K4: Machine Learning
A5: Analytical Thinking & Problem Solving | B5: Analytical Thinking & Problem Solving | C5: 100 | D5: 76.92 | H5: Industry Only | I5: No Match | J5: Professional & Soft Skills
A6: SQL | B6: SQL | C6: 69 | D6: 53.08 | E6: SQL | F6: 32 | G6: 40 | H6: Covered | I6: Exact | J6: Databases & SQL | K6: Databases & SQL
A7: Cloud Platforms (AWS / Azure / GCP) | B7: Cloud Platforms (AWS / Azure / GCP) | C7: 63 | D7: 48.46 | E7: Cloud Platforms (AWS/Azure/GCP) | F7: 13 | G7: 16.25 | H7: Covered | I7: Exact | J7: Cloud & MLOps | K7: Cloud & MLOps
A8: Scikit-learn / NumPy / Pandas | B8: Scikit-learn / NumPy / Pandas | C8: 62 | D8: 47.69 | E8: Machine Learning | F8: 75 | G8: 93.75 | H8: Partially Covered | I8: Conceptual | J8: Machine Learning | K8: Machine Learning
A9: Statistical Analysis | B9: Statistical Analysis | C9: 62 | D9: 47.69 | E9: Statistics | F9: 80 | G9: 100 | H9: Covered | I9: Normalized | J9: Data Analysis & Statistics | K9: Data Analysis & Statistics
A10: Large Language Models (LLMs) | B10: Large Language Models (LLMs) | C10: 48 | D10: 36.92 | E10: Natural Language Processing | F10: 56 | G10: 70 | H10: Partially Covered | I10: Conceptual | J10: Generative AI & NLP | K10: Generative AI & NLP
A11: Generative AI | B11: Generative AI | C11: 45 | D11: 34.62 | E11: Generative AI | F11: 8 | G11: 10 | H11: Covered | I11: Exact | J11: Generative AI & NLP | K11: Generative AI & NLP
A12: PyTorch | B12: PyTorch | C12: 44 | D12: 33.85 | E12: Deep Learning | F12: 63 | G12: 78.75 | H12: Partially Covered | I12: Conceptual | J12: Deep Learning | K12: Deep Learning
A13: TensorFlow / Keras | B13: TensorFlow / Keras | C13: 42 | D13: 32.31 | E13: Deep Learning | F13: 63 | G13: 78.75 | H13: Partially Covered | I13: Conceptual | J13: Deep Learning | K13: Deep Learning
A14: Data Visualization | B14: Data Visualization | C14: 39 | D14: 30 | E14: Data Visualization | F14: 35 | G14: 43.75 | H14: Covered | I14: Exact | J14: Data Visualization & BI | K14: Data Visualization & BI
A15: Natural Language Processing (NLP) | B15: Natural Language Processing (NLP) | C15: 39 | D15: 30 | E15: Natural Language Processing | F15: 56 | G15: 70 | H15: Covered | I15: Normalized | J15: Generative AI & NLP | K15: Generative AI & NLP
A16: Deep Learning | B16: Deep Learning | C16: 38 | D16: 29.23 | E16: Deep Learning | F16: 63 | G16: 78.75 | H16: Covered | I16: Exact | J16: Deep Learning | K16: Deep Learning
A17: Feature Engineering | B17: Feature Engineering | C17: 31 | D17: 23.85 | E17: Data Preprocessing/Wrangling | F17: 19 | G17: 23.75 | H17: Partially Covered | I17: Conceptual | J17: Machine Learning | K17: Data Analysis & Statistics
A18: Prompt Engineering | B18: Prompt Engineering | C18: 28 | D18: 21.54 | H18: Industry Only | I18: No Match | J18: Generative AI & NLP
A19: Model Deployment & Monitoring | B19: Model Deployment & Monitoring | C19: 25 | D19: 19.23 | H19: Industry Only | I19: No Match | J19: Cloud & MLOps
A20: MLOps | B20: MLOps | C20: 24 | D20: 18.46 | H20: Industry Only | I20: No Match | J20: Cloud & MLOps
A21: Data Preprocessing & Cleaning | B21: Data Preprocessing & Cleaning | C21: 18 | D21: 13.85 | E21: Data Preprocessing/Wrangling | F21: 19 | G21: 23.75 | H21: Covered | I21: Normalized | J21: Data Analysis & Statistics | K21: Data Analysis & Statistics
A22: RAG Pipelines & Semantic Search | B22: RAG Pipelines & Semantic Search | C22: 15 | D22: 11.54 | H22: Industry Only | I22: No Match | J22: Generative AI & NLP
A23: Time Series Forecasting | B23: Time Series Forecasting | C23: 15 | D23: 11.54 | E23: Time Series Analysis | F23: 18 | G23: 22.5 | H23: Partially Covered | I23: Conceptual | J23: Data Analysis & Statistics | K23: Data Analysis & Statistics
A24: Data Visualization & Dashboards | B24: Data Visualization & Dashboards | C24: 14 | D24: 10.77 | E24: Business Intelligence | F24: 7 | G24: 8.75 | H24: Partially Covered | I24: Conceptual | J24: Data Visualization & BI | K24: Data Visualization & BI
A25: Experimentation & A/B Testing | B25: Experimentation & A/B Testing | C25: 14 | D25: 10.77 | H25: Industry Only | I25: No Match | J25: Data Analysis & Statistics
A26: Git / Version Control | B26: Git / Version Control | C26: 12 | D26: 9.23 | H26: Industry Only | I26: No Match | J26: Software Engineering
A27: Agentic AI Frameworks | B27: Agentic AI Frameworks | C27: 11 | D27: 8.46 | H27: Industry Only | I27: No Match | J27: Generative AI & NLP
A28: Data Pipelines & Automation | B28: Data Pipelines & Automation | C28: 11 | D28: 8.46 | E28: Data Engineering | F28: 4 | G28: 5 | H28: Partially Covered | I28: Conceptual | J28: Data Engineering & Big Data | K28: Data Engineering & Big Data
A29: Hypothesis Testing | B29: Hypothesis Testing | C29: 11 | D29: 8.46 | E29: Statistics | F29: 80 | G29: 100 | H29: Partially Covered | I29: Conceptual | J29: Data Analysis & Statistics | K29: Data Analysis & Statistics
A30: LLM Orchestration (LangChain / LangGraph / LlamaIndex) | B30: LLM Orchestration (LangChain / LangGraph / LlamaIndex) | C30: 11 | D30: 8.46 | H30: Industry Only | I30: No Match | J30: Generative AI & NLP
A31: R Programming | B31: R Programming | C31: 10 | D31: 7.69 | E31: R Programming | F31: 23 | G31: 28.75 | H31: Covered | I31: Exact | J31: Programming Languages | K31: Programming Languages
A32: Vector Databases & Embeddings | B32: Vector Databases & Embeddings | C32: 9 | D32: 6.92 | H32: Industry Only | I32: No Match | J32: Generative AI & NLP
A33: Anomaly Detection | B33: Anomaly Detection | C33: 8 | D33: 6.15 | E33: Machine Learning | F33: 75 | G33: 93.75 | H33: Partially Covered | I33: Conceptual | J33: Machine Learning | K33: Machine Learning
A34: Communication & Stakeholder Management | B34: Communication & Stakeholder Management | C34: 8 | D34: 6.15 | H34: Industry Only | I34: No Match | J34: Professional & Soft Skills
A35: Docker / Kubernetes | B35: Docker / Kubernetes | C35: 8 | D35: 6.15 | H35: Industry Only | I35: No Match | J35: Cloud & MLOps
A36: ETL / ELT Pipelines & Data Pipelines | B36: ETL / ELT Pipelines & Data Pipelines | C36: 8 | D36: 6.15 | E36: Data Engineering | F36: 4 | G36: 5 | H36: Partially Covered | I36: Conceptual | J36: Data Engineering & Big Data | K36: Data Engineering & Big Data
A37: Exploratory Data Analysis (EDA) | B37: Exploratory Data Analysis (EDA) | C37: 8 | D37: 6.15 | E37: Exploratory Data Analysis | F37: 8 | G37: 10 | H37: Covered | I37: Exact | J37: Data Analysis & Statistics | K37: Data Analysis & Statistics
A38: Big Data (Hadoop / Spark) | B38: Big Data (Hadoop / Spark) | C38: 7 | D38: 5.38 | E38: Big Data | F38: 46 | G38: 57.5 | H38: Covered | I38: Normalized | J38: Data Engineering & Big Data | K38: Data Engineering & Big Data
A39: A/B Testing | B39: A/B Testing | C39: 6 | D39: 4.62 | H39: Industry Only | I39: No Match | J39: Data Analysis & Statistics
A40: PySpark | B40: PySpark | C40: 5 | D40: 3.85 | H40: Industry Only | I40: No Match | J40: Data Engineering & Big Data
...

Sheet Alignment Analysis
A1: Analysis 3
A2: Alignment Analysis
A4: Standardized Skill | B4: Industry Prevalence | C4: Curriculum Prevalence | D4: Alignment | E4: Percentage-Point Difference (pp)
A5: {=_xlfn._xlws.FILTER(Skill_Matching!A2:A82,(Skill_Matching!H2:H82="Covered")+(Skill_Matching!H2:H82="Partially Covered"),"")} -> Python | B5: {=_xlfn._xlws.FILTER(Skill_Matching!D2:D82,(Skill_Matching!H2:H82="Covered")+(Skill_Matching!H2:H82="Partially Covered"),"")} -> 90 | C5: {=_xlfn._xlws.FILTER(Skill_Matching!G2:G82,(Skill_Matching!H2:H82="Covered")+(Skill_Matching!H2:H82="Partially Covered"),"")} -> 98.75 | D5: =IF(OR(B5="",C5="",MAX(B5,C5)=0),"",MIN(B5,C5)/MAX(B5,C5)) -> 0.91139241 | E5: =IF(OR(B5="",C5=""),"",B5-C5) -> -8.75
A6: Machine Learning | B6: 82.31 | C6: 93.75 | D6: =IF(OR(B6="",C6="",MAX(B6,C6)=0),"",MIN(B6,C6)/MAX(B6,C6)) -> 0.87797333 | E6: =IF(OR(B6="",C6=""),"",B6-C6) -> -11.44
A7: SQL | B7: 53.08 | C7: 40 | D7: =IF(OR(B7="",C7="",MAX(B7,C7)=0),"",MIN(B7,C7)/MAX(B7,C7)) -> 0.7535795 | E7: =IF(OR(B7="",C7=""),"",B7-C7) -> 13.08
A8: Cloud Platforms (AWS / Azure / GCP) | B8: 48.46 | C8: 16.25 | D8: =IF(OR(B8="",C8="",MAX(B8,C8)=0),"",MIN(B8,C8)/MAX(B8,C8)) -> 0.33532811 | E8: =IF(OR(B8="",C8=""),"",B8-C8) -> 32.21 | G8: ANALYSIS 3 SUMMARY
A9: Scikit-learn / NumPy / Pandas | B9: 47.69 | C9: 93.75 | D9: =IF(OR(B9="",C9="",MAX(B9,C9)=0),"",MIN(B9,C9)/MAX(B9,C9)) -> 0.50869333 | E9: =IF(OR(B9="",C9=""),"",B9-C9) -> -46.06
A10: Statistical Analysis | B10: 47.69 | C10: 100 | D10: =IF(OR(B10="",C10="",MAX(B10,C10)=0),"",MIN(B10,C10)/MAX(B10,C10)) -> 0.4769 | E10: =IF(OR(B10="",C10=""),"",B10-C10) -> -52.31 | G10: Number of Skills Analyzed | H10: =COUNT(B5:B51) -> 47
A11: Large Language Models (LLMs) | B11: 36.92 | C11: 70 | D11: =IF(OR(B11="",C11="",MAX(B11,C11)=0),"",MIN(B11,C11)/MAX(B11,C11)) -> 0.52742857 | E11: =IF(OR(B11="",C11=""),"",B11-C11) -> -33.08 | G11: Overall Alignment Score | H11: =AVERAGE(D5:D51) -> 0.33178114
A12: Generative AI | B12: 34.62 | C12: 10 | D12: =IF(OR(B12="",C12="",MAX(B12,C12)=0),"",MIN(B12,C12)/MAX(B12,C12)) -> 0.28885038 | E12: =IF(OR(B12="",C12=""),"",B12-C12) -> 24.62 | G12: Highest Alignment Skill | H12: =INDEX(A5:A51,MATCH(MAX(D5:D51),D5:D51,0)) -> Feature Engineering
A13: PyTorch | B13: 33.85 | C13: 78.75 | D13: =IF(OR(B13="",C13="",MAX(B13,C13)=0),"",MIN(B13,C13)/MAX(B13,C13)) -> 0.42984127 | E13: =IF(OR(B13="",C13=""),"",B13-C13) -> -44.9 | G13: Highest Alignment Value | H13: =MAX(D5:D51) -> 0.99580713
A14: TensorFlow / Keras | B14: 32.31 | C14: 78.75 | D14: =IF(OR(B14="",C14="",MAX(B14,C14)=0),"",MIN(B14,C14)/MAX(B14,C14)) -> 0.41028571 | E14: =IF(OR(B14="",C14=""),"",B14-C14) -> -46.44 | G14: Lowest Alignment Skill | H14: =INDEX(A5:A51,MATCH(MIN(D5:D51),D5:D51,0)) -> Causal Inference
A15: Data Visualization | B15: 30 | C15: 43.75 | D15: =IF(OR(B15="",C15="",MAX(B15,C15)=0),"",MIN(B15,C15)/MAX(B15,C15)) -> 0.68571429 | E15: =IF(OR(B15="",C15=""),"",B15-C15) -> -13.75 | G15: Lowest Alignment Value | H15: =MIN(D5:D51) -> 0.0154
A16: Natural Language Processing (NLP) | B16: 30 | C16: 70 | D16: =IF(OR(B16="",C16="",MAX(B16,C16)=0),"",MIN(B16,C16)/MAX(B16,C16)) -> 0.42857143 | E16: =IF(OR(B16="",C16=""),"",B16-C16) -> -40 | G16: Largest Industry Advantage | H16: =INDEX(A5:A51,MATCH(MAX(E5:E51),E5:E51,0)) -> Cloud Platforms (AWS / Azure / GCP)
A17: Deep Learning | B17: 29.23 | C17: 78.75 | D17: =IF(OR(B17="",C17="",MAX(B17,C17)=0),"",MIN(B17,C17)/MAX(B17,C17)) -> 0.3711746 | E17: =IF(OR(B17="",C17=""),"",B17-C17) -> -49.52 | G17: Largest Industry Advantage Value | H17: =MAX(E5:E51) -> 32.21
A18: Feature Engineering | B18: 23.85 | C18: 23.75 | D18: =IF(OR(B18="",C18="",MAX(B18,C18)=0),"",MIN(B18,C18)/MAX(B18,C18)) -> 0.99580713 | E18: =IF(OR(B18="",C18=""),"",B18-C18) -> 0.1 | G18: Largest Curriculum Advantage | H18: =INDEX(A5:A51,MATCH(MIN(E5:E51),E5:E51,0)) -> Causal Inference
A19: Data Preprocessing & Cleaning | B19: 13.85 | C19: 23.75 | D19: =IF(OR(B19="",C19="",MAX(B19,C19)=0),"",MIN(B19,C19)/MAX(B19,C19)) -> 0.58315789 | E19: =IF(OR(B19="",C19=""),"",B19-C19) -> -9.9 | G19: Largest Curriculum Advantage Value | H19: =MIN(E5:E51) -> -98.46
A20: Time Series Forecasting | B20: 11.54 | C20: 22.5 | D20: =IF(OR(B20="",C20="",MAX(B20,C20)=0),"",MIN(B20,C20)/MAX(B20,C20)) -> 0.51288889 | E20: =IF(OR(B20="",C20=""),"",B20-C20) -> -10.96
A21: Data Visualization & Dashboards | B21: 10.77 | C21: 8.75 | D21: =IF(OR(B21="",C21="",MAX(B21,C21)=0),"",MIN(B21,C21)/MAX(B21,C21)) -> 0.81244197 | E21: =IF(OR(B21="",C21=""),"",B21-C21) -> 2.02
A22: Data Pipelines & Automation | B22: 8.46 | C22: 5 | D22: =IF(OR(B22="",C22="",MAX(B22,C22)=0),"",MIN(B22,C22)/MAX(B22,C22)) -> 0.59101655 | E22: =IF(OR(B22="",C22=""),"",B22-C22) -> 3.46 | G22: Top 10 Alignment Skills | H22: Alignment
A23: Hypothesis Testing | B23: 8.46 | C23: 100 | D23: =IF(OR(B23="",C23="",MAX(B23,C23)=0),"",MIN(B23,C23)/MAX(B23,C23)) -> 0.0846 | E23: =IF(OR(B23="",C23=""),"",B23-C23) -> -91.54 | G23: =INDEX($A$5:$A$51,MATCH(LARGE($D$5:$D$51,ROWS($G$22:G22)),$D$5:$D$51,0)) -> Feature Engineering | H23: =LARGE($D$5:$D$51,ROWS($H$22:H22)) -> 0.99580713
A24: R Programming | B24: 7.69 | C24: 28.75 | D24: =IF(OR(B24="",C24="",MAX(B24,C24)=0),"",MIN(B24,C24)/MAX(B24,C24)) -> 0.26747826 | E24: =IF(OR(B24="",C24=""),"",B24-C24) -> -21.06 | G24: =INDEX($A$5:$A$51,MATCH(LARGE($D$5:$D$51,ROWS($G$22:G23)),$D$5:$D$51,0)) -> Python | H24: =LARGE($D$5:$D$51,ROWS($H$22:H23)) -> 0.91139241
A25: Anomaly Detection | B25: 6.15 | C25: 93.75 | D25: =IF(OR(B25="",C25="",MAX(B25,C25)=0),"",MIN(B25,C25)/MAX(B25,C25)) -> 0.0656 | E25: =IF(OR(B25="",C25=""),"",B25-C25) -> -87.6 | G25: =INDEX($A$5:$A$51,MATCH(LARGE($D$5:$D$51,ROWS($G$22:G24)),$D$5:$D$51,0)) -> Machine Learning | H25: =LARGE($D$5:$D$51,ROWS($H$22:H24)) -> 0.87797333
A26: ETL / ELT Pipelines & Data Pipelines | B26: 6.15 | C26: 5 | D26: =IF(OR(B26="",C26="",MAX(B26,C26)=0),"",MIN(B26,C26)/MAX(B26,C26)) -> 0.81300813 | E26: =IF(OR(B26="",C26=""),"",B26-C26) -> 1.15 | G26: =INDEX($A$5:$A$51,MATCH(LARGE($D$5:$D$51,ROWS($G$22:G25)),$D$5:$D$51,0)) -> ETL / ELT Pipelines & Data Pipelines | H26: =LARGE($D$5:$D$51,ROWS($H$22:H25)) -> 0.81300813
A27: Exploratory Data Analysis (EDA) | B27: 6.15 | C27: 10 | D27: =IF(OR(B27="",C27="",MAX(B27,C27)=0),"",MIN(B27,C27)/MAX(B27,C27)) -> 0.615 | E27: =IF(OR(B27="",C27=""),"",B27-C27) -> -3.85 | G27: =INDEX($A$5:$A$51,MATCH(LARGE($D$5:$D$51,ROWS($G$22:G26)),$D$5:$D$51,0)) -> Data Visualization & Dashboards | H27: =LARGE($D$5:$D$51,ROWS($H$22:H26)) -> 0.81244197
A28: Big Data (Hadoop / Spark) | B28: 5.38 | C28: 57.5 | D28: =IF(OR(B28="",C28="",MAX(B28,C28)=0),"",MIN(B28,C28)/MAX(B28,C28)) -> 0.093565217 | E28: =IF(OR(B28="",C28=""),"",B28-C28) -> -52.12 | G28: =INDEX($A$5:$A$51,MATCH(LARGE($D$5:$D$51,ROWS($G$22:G27)),$D$5:$D$51,0)) -> SQL | H28: =LARGE($D$5:$D$51,ROWS($H$22:H27)) -> 0.7535795
A29: Artificial Intelligence | B29: 3.08 | C29: 76.25 | D29: =IF(OR(B29="",C29="",MAX(B29,C29)=0),"",MIN(B29,C29)/MAX(B29,C29)) -> 0.040393443 | E29: =IF(OR(B29="",C29=""),"",B29-C29) -> -73.17 | G29: =INDEX($A$5:$A$51,MATCH(LARGE($D$5:$D$51,ROWS($G$22:G28)),$D$5:$D$51,0)) -> Data Visualization | H29: =LARGE($D$5:$D$51,ROWS($H$22:H28)) -> 0.68571429
A30: Data Preprocessing & Augmentation | B30: 3.08 | C30: 23.75 | D30: =IF(OR(B30="",C30="",MAX(B30,C30)=0),"",MIN(B30,C30)/MAX(B30,C30)) -> 0.12968421 | E30: =IF(OR(B30="",C30=""),"",B30-C30) -> -20.67 | G30: =INDEX($A$5:$A$51,MATCH(LARGE($D$5:$D$51,ROWS($G$22:G29)),$D$5:$D$51,0)) -> Tableau | H30: =LARGE($D$5:$D$51,ROWS($H$22:H29)) -> 0.616
A31: Model Evaluation | B31: 3.08 | C31: 93.75 | D31: =IF(OR(B31="",C31="",MAX(B31,C31)=0),"",MIN(B31,C31)/MAX(B31,C31)) -> 0.032853333 | E31: =IF(OR(B31="",C31=""),"",B31-C31) -> -90.67 | G31: =INDEX($A$5:$A$51,MATCH(LARGE($D$5:$D$51,ROWS($G$22:G30)),$D$5:$D$51,0)) -> Exploratory Data Analysis (EDA) | H31: =LARGE($D$5:$D$51,ROWS($H$22:H30)) -> 0.615
A32: Predictive Modeling | B32: 3.08 | C32: 46.25 | D32: =IF(OR(B32="",C32="",MAX(B32,C32)=0),"",MIN(B32,C32)/MAX(B32,C32)) -> 0.066594595 | E32: =IF(OR(B32="",C32=""),"",B32-C32) -> -43.17 | G32: =INDEX($A$5:$A$51,MATCH(LARGE($D$5:$D$51,ROWS($G$22:G31)),$D$5:$D$51,0)) -> Data Pipelines & Automation | H32: =LARGE($D$5:$D$51,ROWS($H$22:H31)) -> 0.59101655
A33: Statistical Modeling | B33: 3.08 | C33: 100 | D33: =IF(OR(B33="",C33="",MAX(B33,C33)=0),"",MIN(B33,C33)/MAX(B33,C33)) -> 0.0308 | E33: =IF(OR(B33="",C33=""),"",B33-C33) -> -96.92
A34: Supervised Learning | B34: 3.08 | C34: 33.75 | D34: =IF(OR(B34="",C34="",MAX(B34,C34)=0),"",MIN(B34,C34)/MAX(B34,C34)) -> 0.091259259 | E34: =IF(OR(B34="",C34=""),"",B34-C34) -> -30.67
A35: Tableau | B35: 3.08 | C35: 5 | D35: =IF(OR(B35="",C35="",MAX(B35,C35)=0),"",MIN(B35,C35)/MAX(B35,C35)) -> 0.616 | E35: =IF(OR(B35="",C35=""),"",B35-C35) -> -1.92
A36: Customer Segmentation | B36: 2.31 | C36: 27.5 | D36: =IF(OR(B36="",C36="",MAX(B36,C36)=0),"",MIN(B36,C36)/MAX(B36,C36)) -> 0.084 | E36: =IF(OR(B36="",C36=""),"",B36-C36) -> -25.19
A37: NoSQL Databases | B37: 2.31 | C37: 12.5 | D37: =IF(OR(B37="",C37="",MAX(B37,C37)=0),"",MIN(B37,C37)/MAX(B37,C37)) -> 0.1848 | E37: =IF(OR(B37="",C37=""),"",B37-C37) -> -10.19
A38: React / Frontend Frameworks | B38: 2.31 | C38: 6.25 | D38: =IF(OR(B38="",C38="",MAX(B38,C38)=0),"",MIN(B38,C38)/MAX(B38,C38)) -> 0.3696 | E38: =IF(OR(B38="",C38=""),"",B38-C38) -> -3.94
A39: SQL / Relational Databases | B39: 2.31 | C39: 61.25 | D39: =IF(OR(B39="",C39="",MAX(B39,C39)=0),"",MIN(B39,C39)/MAX(B39,C39)) -> 0.037714286 | E39: =IF(OR(B39="",C39=""),"",B39-C39) -> -58.94
A40: Algorithms & Data Structures | B40: 1.54 | C40: 90 | D40: =IF(OR(B40="",C40="",MAX(B40,C40)=0),"",MIN(B40,C40)/MAX(B40,C40)) -> 0.017111111 | E40: =IF(OR(B40="",C40=""),"",B40-C40) -> -88.46
A41: Bayesian Methods / Causal Inference | B41: 1.54 | C41: 6.25 | D41: =IF(OR(B41="",C41="",MAX(B41,C41)=0),"",MIN(B41,C41)/MAX(B41,C41)) -> 0.2464 | E41: =IF(OR(B41="",C41=""),"",B41-C41) -> -4.71
...

Sheet Skill Gap Analysis
A1: Analysis 4
A2: Skill Gap Analysis
A4: Standardized Skill | B4: Industry Prevalence | C4: Curriculum Prevalence | D4: Skill Gap | E4: Absolute Gap | F4: Gap Direction
A5: ='Alignment Analysis'!A5 -> Python | B5: ='Alignment Analysis'!B5 -> 90 | C5: ='Alignment Analysis'!C5 -> 98.75 | D5: =B5-C5 -> -8.75 | E5: =ABS(D5) -> 8.75 | F5: =IF(D5>0,"Industry Higher",IF(D5<0,"Curriculum Higher","Equal")) -> Curriculum Higher
A6: ='Alignment Analysis'!A6 -> Machine Learning | B6: ='Alignment Analysis'!B6 -> 82.31 | C6: ='Alignment Analysis'!C6 -> 93.75 | D6: =B6-C6 -> -11.44 | E6: =ABS(D6) -> 11.44 | F6: =IF(D6>0,"Industry Higher",IF(D6<0,"Curriculum Higher","Equal")) -> Curriculum Higher
A7: ='Alignment Analysis'!A7 -> SQL | B7: ='Alignment Analysis'!B7 -> 53.08 | C7: ='Alignment Analysis'!C7 -> 40 | D7: =B7-C7 -> 13.08 | E7: =ABS(D7) -> 13.08 | F7: =IF(D7>0,"Industry Higher",IF(D7<0,"Curriculum Higher","Equal")) -> Industry Higher
A8: ='Alignment Analysis'!A8 -> Cloud Platforms (AWS / Azure / GCP) | B8: ='Alignment Analysis'!B8 -> 48.46 | C8: ='Alignment Analysis'!C8 -> 16.25 | D8: =B8-C8 -> 32.21 | E8: =ABS(D8) -> 32.21 | F8: =IF(D8>0,"Industry Higher",IF(D8<0,"Curriculum Higher","Equal")) -> Industry Higher
A9: ='Alignment Analysis'!A9 -> Scikit-learn / NumPy / Pandas | B9: ='Alignment Analysis'!B9 -> 47.69 | C9: ='Alignment Analysis'!C9 -> 93.75 | D9: =B9-C9 -> -46.06 | E9: =ABS(D9) -> 46.06 | F9: =IF(D9>0,"Industry Higher",IF(D9<0,"Curriculum Higher","Equal")) -> Curriculum Higher | I9: Analysis 4 Summary
A10: ='Alignment Analysis'!A10 -> Statistical Analysis | B10: ='Alignment Analysis'!B10 -> 47.69 | C10: ='Alignment Analysis'!C10 -> 100 | D10: =B10-C10 -> -52.31 | E10: =ABS(D10) -> 52.31 | F10: =IF(D10>0,"Industry Higher",IF(D10<0,"Curriculum Higher","Equal")) -> Curriculum Higher
A11: ='Alignment Analysis'!A11 -> Large Language Models (LLMs) | B11: ='Alignment Analysis'!B11 -> 36.92 | C11: ='Alignment Analysis'!C11 -> 70 | D11: =B11-C11 -> -33.08 | E11: =ABS(D11) -> 33.08 | F11: =IF(D11>0,"Industry Higher",IF(D11<0,"Curriculum Higher","Equal")) -> Curriculum Higher | H11: Result | I11: Skill | J11: Value
A12: ='Alignment Analysis'!A12 -> Generative AI | B12: ='Alignment Analysis'!B12 -> 34.62 | C12: ='Alignment Analysis'!C12 -> 10 | D12: =B12-C12 -> 24.62 | E12: =ABS(D12) -> 24.62 | F12: =IF(D12>0,"Industry Higher",IF(D12<0,"Curriculum Higher","Equal")) -> Industry Higher | H12: Largest Industry Gap | I12: =INDEX(A5:A51,MATCH(MAX(D5:D51),D5:D51,0)) -> Cloud Platforms (AWS / Azure / GCP) | J12: =MAX(D5:D51) -> 32.21
A13: ='Alignment Analysis'!A13 -> PyTorch | B13: ='Alignment Analysis'!B13 -> 33.85 | C13: ='Alignment Analysis'!C13 -> 78.75 | D13: =B13-C13 -> -44.9 | E13: =ABS(D13) -> 44.9 | F13: =IF(D13>0,"Industry Higher",IF(D13<0,"Curriculum Higher","Equal")) -> Curriculum Higher | H13: Largest Curriculum Gap | I13: =INDEX(A5:A51,MATCH(MIN(D5:D51),D5:D51,0)) -> Causal Inference | J13: =MIN(D5:D51) -> -98.46
A14: ='Alignment Analysis'!A14 -> TensorFlow / Keras | B14: ='Alignment Analysis'!B14 -> 32.31 | C14: ='Alignment Analysis'!C14 -> 78.75 | D14: =B14-C14 -> -46.44 | E14: =ABS(D14) -> 46.44 | F14: =IF(D14>0,"Industry Higher",IF(D14<0,"Curriculum Higher","Equal")) -> Curriculum Higher | H14: Largest Absolute Gap | I14: =INDEX(A5:A51,MATCH(MAX(E5:E51),E5:E51,0)) -> Causal Inference | J14: =MAX(E5:E51) -> 98.46
A15: ='Alignment Analysis'!A15 -> Data Visualization | B15: ='Alignment Analysis'!B15 -> 30 | C15: ='Alignment Analysis'!C15 -> 43.75 | D15: =B15-C15 -> -13.75 | E15: =ABS(D15) -> 13.75 | F15: =IF(D15>0,"Industry Higher",IF(D15<0,"Curriculum Higher","Equal")) -> Curriculum Higher
A16: ='Alignment Analysis'!A16 -> Natural Language Processing (NLP) | B16: ='Alignment Analysis'!B16 -> 30 | C16: ='Alignment Analysis'!C16 -> 70 | D16: =B16-C16 -> -40 | E16: =ABS(D16) -> 40 | F16: =IF(D16>0,"Industry Higher",IF(D16<0,"Curriculum Higher","Equal")) -> Curriculum Higher
A17: ='Alignment Analysis'!A17 -> Deep Learning | B17: ='Alignment Analysis'!B17 -> 29.23 | C17: ='Alignment Analysis'!C17 -> 78.75 | D17: =B17-C17 -> -49.52 | E17: =ABS(D17) -> 49.52 | F17: =IF(D17>0,"Industry Higher",IF(D17<0,"Curriculum Higher","Equal")) -> Curriculum Higher
A18: ='Alignment Analysis'!A18 -> Feature Engineering | B18: ='Alignment Analysis'!B18 -> 23.85 | C18: ='Alignment Analysis'!C18 -> 23.75 | D18: =B18-C18 -> 0.1 | E18: =ABS(D18) -> 0.1 | F18: =IF(D18>0,"Industry Higher",IF(D18<0,"Curriculum Higher","Equal")) -> Industry Higher
A19: ='Alignment Analysis'!A19 -> Data Preprocessing & Cleaning | B19: ='Alignment Analysis'!B19 -> 13.85 | C19: ='Alignment Analysis'!C19 -> 23.75 | D19: =B19-C19 -> -9.9 | E19: =ABS(D19) -> 9.9 | F19: =IF(D19>0,"Industry Higher",IF(D19<0,"Curriculum Higher","Equal")) -> Curriculum Higher
A20: ='Alignment Analysis'!A20 -> Time Series Forecasting | B20: ='Alignment Analysis'!B20 -> 11.54 | C20: ='Alignment Analysis'!C20 -> 22.5 | D20: =B20-C20 -> -10.96 | E20: =ABS(D20) -> 10.96 | F20: =IF(D20>0,"Industry Higher",IF(D20<0,"Curriculum Higher","Equal")) -> Curriculum Higher
A21: ='Alignment Analysis'!A21 -> Data Visualization & Dashboards | B21: ='Alignment Analysis'!B21 -> 10.77 | C21: ='Alignment Analysis'!C21 -> 8.75 | D21: =B21-C21 -> 2.02 | E21: =ABS(D21) -> 2.02 | F21: =IF(D21>0,"Industry Higher",IF(D21<0,"Curriculum Higher","Equal")) -> Industry Higher
A22: ='Alignment Analysis'!A22 -> Data Pipelines & Automation | B22: ='Alignment Analysis'!B22 -> 8.46 | C22: ='Alignment Analysis'!C22 -> 5 | D22: =B22-C22 -> 3.46 | E22: =ABS(D22) -> 3.46 | F22: =IF(D22>0,"Industry Higher",IF(D22<0,"Curriculum Higher","Equal")) -> Industry Higher
A23: ='Alignment Analysis'!A23 -> Hypothesis Testing | B23: ='Alignment Analysis'!B23 -> 8.46 | C23: ='Alignment Analysis'!C23 -> 100 | D23: =B23-C23 -> -91.54 | E23: =ABS(D23) -> 91.54 | F23: =IF(D23>0,"Industry Higher",IF(D23<0,"Curriculum Higher","Equal")) -> Curriculum Higher
A24: ='Alignment Analysis'!A24 -> R Programming | B24: ='Alignment Analysis'!B24 -> 7.69 | C24: ='Alignment Analysis'!C24 -> 28.75 | D24: =B24-C24 -> -21.06 | E24: =ABS(D24) -> 21.06 | F24: =IF(D24>0,"Industry Higher",IF(D24<0,"Curriculum Higher","Equal")) -> Curriculum Higher
A25: ='Alignment Analysis'!A25 -> Anomaly Detection | B25: ='Alignment Analysis'!B25 -> 6.15 | C25: ='Alignment Analysis'!C25 -> 93.75 | D25: =B25-C25 -> -87.6 | E25: =ABS(D25) -> 87.6 | F25: =IF(D25>0,"Industry Higher",IF(D25<0,"Curriculum Higher","Equal")) -> Curriculum Higher
A26: ='Alignment Analysis'!A26 -> ETL / ELT Pipelines & Data Pipelines | B26: ='Alignment Analysis'!B26 -> 6.15 | C26: ='Alignment Analysis'!C26 -> 5 | D26: =B26-C26 -> 1.15 | E26: =ABS(D26) -> 1.15 | F26: =IF(D26>0,"Industry Higher",IF(D26<0,"Curriculum Higher","Equal")) -> Industry Higher
... A51: ='Alignment Analysis'!A51 -> AI Safety & Responsible AI | B51: ='Alignment Analysis'!B51 -> 0.77 | C51: ='Alignment Analysis'!C51 -> 11.25 | D51: =B51-C51 -> -10.48 | E51: =ABS(D51) -> 10.48 | F51: =IF(D51>0,"Industry Higher",IF(D51<0,"Curriculum Higher","Equal")) -> Curriculum Higher
A91: Standardized Skill | B91: Absolute Gap
A92: =INDEX($A$5:$A$51,MATCH(B92,$E$5:$E$51,0)) -> Causal Inference | B92: =LARGE($E$5:$E$51,ROWS($B$36:B36)) -> 98.46
A93: =INDEX($A$5:$A$51,MATCH(B93,$E$5:$E$51,0)) -> Statistical Modeling | B93: =LARGE($E$5:$E$51,ROWS($B$36:B37)) -> 96.92
A94: =INDEX($A$5:$A$51,MATCH(B94,$E$5:$E$51,0)) -> Hypothesis Testing | B94: =LARGE($E$5:$E$51,ROWS($B$36:B38)) -> 91.54
A95: =INDEX($A$5:$A$51,MATCH(B95,$E$5:$E$51,0)) -> Model Evaluation | B95: =LARGE($E$5:$E$51,ROWS($B$36:B39)) -> 90.67
A96: =INDEX($A$5:$A$51,MATCH(B96,$E$5:$E$51,0)) -> Algorithms & Data Structures | B96: =LARGE($E$5:$E$51,ROWS($B$36:B40)) -> 88.46
A97: =INDEX($A$5:$A$51,MATCH(B97,$E$5:$E$51,0)) -> Anomaly Detection | B97: =LARGE($E$5:$E$51,ROWS($B$36:B41)) -> 87.6
A98: =INDEX($A$5:$A$51,MATCH(B98,$E$5:$E$51,0)) -> Data Mining | B98: =LARGE($E$5:$E$51,ROWS($B$36:B42)) -> 74.71
A99: =INDEX($A$5:$A$51,MATCH(B99,$E$5:$E$51,0)) -> Artificial Intelligence | B99: =LARGE($E$5:$E$51,ROWS($B$36:B43)) -> 73.17
A100: =INDEX($A$5:$A$51,MATCH(B100,$E$5:$E$51,0)) -> Predictive Analytics | B100: =LARGE($E$5:$E$51,ROWS($B$36:B44)) -> 68.46
A101: =INDEX($A$5:$A$51,MATCH(B101,$E$5:$E$51,0)) -> SQL / Relational Databases | B101: =LARGE($E$5:$E$51,ROWS($B$36:B45)) -> 58.94

Sheet Curriculum Coverage
A1: Analysis 5
A2: Curriculum Coverage Analysis
A4: Standardized Skill | B4: Coverage Status | C4: Priority Tier | D4: Skill Category | E4: Industry Frequency | F4: Strict Coverage | G4: Braod Coverage
A5: {=IFERROR(INDEX(Skill_Matching!$A$2:$A$200,_xlfn.AGGREGATE(15,6,(ROW(Skill_Matching!$A$2:$A$200)-ROW(Skill_Matching!$A$2)+1)/(Skill_Matching!$D$2:$D$200<>""),ROWS($A$5:A5))),"")} -> Python | B5: {=IF(A5="","",INDEX(Skill_Matching!$H$2:$H$200,_xlfn.AGGREGATE(15,6,(ROW(Skill_Matching!$A$2:$A$200)-ROW(Skill_Matching!$A$2)+1)/(Skill_Matching!$D$2:$D$200<>""),ROWS($A$5:A5))))} -> Covered | C5: =IF(E5="","",IF(E5>=50,"Tier 1",IF(E5>=25,"Tier 2",IF(E5>=10,"Tier 3","Tier 4")))) -> Tier 1 | D5: =_xlfn.XLOOKUP(A5,Skill_Matching!$A$2:$A$200,Skill_Matching!$J$2:$J$200,"") -> Programming Languages | E5: =_xlfn.XLOOKUP(A5,Skill_Matching!$A$2:$A$200,Skill_Matching!$D$2:$D$200,"") -> 90 | F5: =IF(B5="Covered",1,0) -> 1 | G5: =IF(OR(B5="Covered",B5="Partially Covered"),1,0) -> 1
A6: {=IFERROR(INDEX(Skill_Matching!$A$2:$A$200,_xlfn.AGGREGATE(15,6,(ROW(Skill_Matching!$A$2:$A$200)-ROW(Skill_Matching!$A$2)+1)/(Skill_Matching!$D$2:$D$200<>""),ROWS($A$5:A6))),"")} -> Communication & Collaboration | B6: {=IF(A6="","",INDEX(Skill_Matching!$H$2:$H$200,_xlfn.AGGREGATE(15,6,(ROW(Skill_Matching!$A$2:$A$200)-ROW(Skill_Matching!$A$2)+1)/(Skill_Matching!$D$2:$D$200<>""),ROWS($A$5:A6))))} -> Industry Only | C6: =IF(E6="","",IF(E6>=50,"Tier 1",IF(E6>=25,"Tier 2",IF(E6>=10,"Tier 3","Tier 4")))) -> Tier 1 | D6: =_xlfn.XLOOKUP(A6,Skill_Matching!$A$2:$A$200,Skill_Matching!$J$2:$J$200,"") -> Professional & Soft Skills | E6: =_xlfn.XLOOKUP(A6,Skill_Matching!$A$2:$A$200,Skill_Matching!$D$2:$D$200,"") -> 84.62 | F6: =IF(B6="Covered",1,0) -> 0 | G6: =IF(OR(B6="Covered",B6="Partially Covered"),1,0) -> 0
A7: {=IFERROR(INDEX(Skill_Matching!$A$2:$A$200,_xlfn.AGGREGATE(15,6,(ROW(Skill_Matching!$A$2:$A$200)-ROW(Skill_Matching!$A$2)+1)/(Skill_Matching!$D$2:$D$200<>""),ROWS($A$5:A7))),"")} -> Machine Learning | B7: {=IF(A7="","",INDEX(Skill_Matching!$H$2:$H$200,_xlfn.AGGREGATE(15,6,(ROW(Skill_Matching!$A$2:$A$200)-ROW(Skill_Matching!$A$2)+1)/(Skill_Matching!$D$2:$D$200<>""),ROWS($A$5:A7))))} -> Covered | C7: =IF(E7="","",IF(E7>=50,"Tier 1",IF(E7>=25,"Tier 2",IF(E7>=10,"Tier 3","Tier 4")))) -> Tier 1 | D7: =_xlfn.XLOOKUP(A7,Skill_Matching!$A$2:$A$200,Skill_Matching!$J$2:$J$200,"") -> Machine Learning | E7: =_xlfn.XLOOKUP(A7,Skill_Matching!$A$2:$A$200,Skill_Matching!$D$2:$D$200,"") -> 82.31 | F7: =IF(B7="Covered",1,0) -> 1 | G7: =IF(OR(B7="Covered",B7="Partially Covered"),1,0) -> 1
A8: {=IFERROR(INDEX(Skill_Matching!$A$2:$A$200,_xlfn.AGGREGATE(15,6,(ROW(Skill_Matching!$A$2:$A$200)-ROW(Skill_Matching!$A$2)+1)/(Skill_Matching!$D$2:$D$200<>""),ROWS($A$5:A8))),"")} -> Analytical Thinking & Problem Solving | B8: {=IF(A8="","",INDEX(Skill_Matching!$H$2:$H$200,_xlfn.AGGREGATE(15,6,(ROW(Skill_Matching!$A$2:$A$200)-ROW(Skill_Matching!$A$2)+1)/(Skill_Matching!$D$2:$D$200<>""),ROWS($A$5:A8))))} -> Industry Only | C8: =IF(E8="","",IF(E8>=50,"Tier 1",IF(E8>=25,"Tier 2",IF(E8>=10,"Tier 3","Tier 4")))) -> Tier 1 | D8: =_xlfn.XLOOKUP(A8,Skill_Matching!$A$2:$A$200,Skill_Matching!$J$2:$J$200,"") -> Professional & Soft Skills | E8: =_xlfn.XLOOKUP(A8,Skill_Matching!$A$2:$A$200,Skill_Matching!$D$2:$D$200,"") -> 76.92 | F8: =IF(B8="Covered",1,0) -> 0 | G8: =IF(OR(B8="Covered",B8="Partially Covered"),1,0) -> 0
A9: {=IFERROR(INDEX(Skill_Matching!$A$2:$A$200,_xlfn.AGGREGATE(15,6,(ROW(Skill_Matching!$A$2:$A$200)-ROW(Skill_Matching!$A$2)+1)/(Skill_Matching!$D$2:$D$200<>""),ROWS($A$5:A9))),"")} -> SQL | B9: {=IF(A9="","",INDEX(Skill_Matching!$H$2:$H$200,_xlfn.AGGREGATE(15,6,(ROW(Skill_Matching!$A$2:$A$200)-ROW(Skill_Matching!$A$2)+1)/(Skill_Matching!$D$2:$D$200<>""),ROWS($A$5:A9))))} -> Covered | C9: =IF(E9="","",IF(E9>=50,"Tier 1",IF(E9>=25,"Tier 2",IF(E9>=10,"Tier 3","Tier 4")))) -> Tier 1 | D9: =_xlfn.XLOOKUP(A9,Skill_Matching!$A$2:$A$200,Skill_Matching!$J$2:$J$200,"") -> Databases & SQL | E9: =_xlfn.XLOOKUP(A9,Skill_Matching!$A$2:$A$200,Skill_Matching!$D$2:$D$200,"") -> 53.08 | F9: =IF(B9="Covered",1,0) -> 1 | G9: =IF(OR(B9="Covered",B9="Partially Covered"),1,0) -> 1
A10: {=IFERROR(INDEX(Skill_Matching!$A$2:$A$200,_xlfn.AGGREGATE(15,6,(ROW(Skill_Matching!$A$2:$A$200)-ROW(Skill_Matching!$A$2)+1)/(Skill_Matching!$D$2:$D$200<>""),ROWS($A$5:A10))),"")} -> Cloud Platforms (AWS / Azure / GCP) | B10: {=IF(A10="","",INDEX(Skill_Matching!$H$2:$H$200,_xlfn.AGGREGATE(15,6,(ROW(Skill_Matching!$A$2:$A$200)-ROW(Skill_Matching!$A$2)+1)/(Skill_Matching!$D$2:$D$200<>""),ROWS($A$5:A10))))} -> Covered | C10: =IF(E10="","",IF(E10>=50,"Tier 1",IF(E10>=25,"Tier 2",IF(E10>=10,"Tier 3","Tier 4")))) -> Tier 2 | D10: =_xlfn.XLOOKUP(A10,Skill_Matching!$A$2:$A$200,Skill_Matching!$J$2:$J$200,"") -> Cloud & MLOps | E10: =_xlfn.XLOOKUP(A10,Skill_Matching!$A$2:$A$200,Skill_Matching!$D$2:$D$200,"") -> 48.46 | F10: =IF(B10="Covered",1,0) -> 1 | G10: =IF(OR(B10="Covered",B10="Partially Covered"),1,0) -> 1
A11: {=IFERROR(INDEX(Skill_Matching!$A$2:$A$200,_xlfn.AGGREGATE(15,6,(ROW(Skill_Matching!$A$2:$A$200)-ROW(Skill_Matching!$A$2)+1)/(Skill_Matching!$D$2:$D$200<>""),ROWS($A$5:A11))),"")} -> Scikit-learn / NumPy / Pandas | B11: {=IF(A11="","",INDEX(Skill_Matching!$H$2:$H$200,_xlfn.AGGREGATE(15,6,(ROW(Skill_Matching!$A$2:$A$200)-ROW(Skill_Matching!$A$2)+1)/(Skill_Matching!$D$2:$D$200<>""),ROWS($A$5:A11))))} -> Partially Covered | C11: =IF(E11="","",IF(E11>=50,"Tier 1",IF(E11>=25,"Tier 2",IF(E11>=10,"Tier 3","Tier 4")))) -> Tier 2 | D11: =_xlfn.XLOOKUP(A11,Skill_Matching!$A$2:$A$200,Skill_Matching!$J$2:$J$200,"") -> Machine Learning | E11: =_xlfn.XLOOKUP(A11,Skill_Matching!$A$2:$A$200,Skill_Matching!$D$2:$D$200,"") -> 47.69 | F11: =IF(B11="Covered",1,0) -> 0 | G11: =IF(OR(B11="Covered",B11="Partially Covered"),1,0) -> 1
A12: {=IFERROR(INDEX(Skill_Matching!$A$2:$A$200,_xlfn.AGGREGATE(15,6,(ROW(Skill_Matching!$A$2:$A$200)-ROW(Skill_Matching!$A$2)+1)/(Skill_Matching!$D$2:$D$200<>""),ROWS($A$5:A12))),"")} -> Statistical Analysis | B12: {=IF(A12="","",INDEX(Skill_Matching!$H$2:$H$200,_xlfn.AGGREGATE(15,6,(ROW(Skill_Matching!$A$2:$A$200)-ROW(Skill_Matching!$A$2)+1)/(Skill_Matching!$D$2:$D$200<>""),ROWS($A$5:A12))))} -> Covered | C12: =IF(E12="","",IF(E12>=50,"Tier 1",IF(E12>=25,"Tier 2",IF(E12>=10,"Tier 3","Tier 4")))) -> Tier 2 | D12: =_xlfn.XLOOKUP(A12,Skill_Matching!$A$2:$A$200,Skill_Matching!$J$2:$J$200,"") -> Data Analysis & Statistics | E12: =_xlfn.XLOOKUP(A12,Skill_Matching!$A$2:$A$200,Skill_Matching!$D$2:$D$200,"") -> 47.69 | F12: =IF(B12="Covered",1,0) -> 1 | G12: =IF(OR(B12="Covered",B12="Partially Covered"),1,0) -> 1
A13: {=IFERROR(INDEX(Skill_Matching!$A$2:$A$200,_xlfn.AGGREGATE(15,6,(ROW(Skill_Matching!$A$2:$A$200)-ROW(Skill_Matching!$A$2)+1)/(Skill_Matching!$D$2:$D$200<>""),ROWS($A$5:A13))),"")} -> Large Language Models (LLMs) | B13: {=IF(A13="","",INDEX(Skill_Matching!$H$2:$H$200,_xlfn.AGGREGATE(15,6,(ROW(Skill_Matching!$A$2:$A$200)-ROW(Skill_Matching!$A$2)+1)/(Skill_Matching!$D$2:$D$200<>""),ROWS($A$5:A13))))} -> Partially Covered | C13: =IF(E13="","",IF(E13>=50,"Tier 1",IF(E13>=25,"Tier 2",IF(E13>=10,"Tier 3","Tier 4")))) -> Tier 2 | D13: =_xlfn.XLOOKUP(A13,Skill_Matching!$A$2:$A$200,Skill_Matching!$J$2:$J$200,"") -> Generative AI & NLP | E13: =_xlfn.XLOOKUP(A13,Skill_Matching!$A$2:$A$200,Skill_Matching!$D$2:$D$200,"") -> 36.92 | F13: =IF(B13="Covered",1,0) -> 0 | G13: =IF(OR(B13="Covered",B13="Partially Covered"),1,0) -> 1
A14: {=IFERROR(INDEX(Skill_Matching!$A$2:$A$200,_xlfn.AGGREGATE(15,6,(ROW(Skill_Matching!$A$2:$A$200)-ROW(Skill_Matching!$A$2)+1)/(Skill_Matching!$D$2:$D$200<>""),ROWS($A$5:A14))),"")} -> Generative AI | B14: {=IF(A14="","",INDEX(Skill_Matching!$H$2:$H$200,_xlfn.AGGREGATE(15,6,(ROW(Skill_Matching!$A$2:$A$200)-ROW(Skill_Matching!$A$2)+1)/(Skill_Matching!$D$2:$D$200<>""),ROWS($A$5:A14))))} -> Covered | C14: =IF(E14="","",IF(E14>=50,"Tier 1",IF(E14>=25,"Tier 2",IF(E14>=10,"Tier 3","Tier 4")))) -> Tier 2 | D14: =_xlfn.XLOOKUP(A14,Skill_Matching!$A$2:$A$200,Skill_Matching!$J$2:$J$200,"") -> Generative AI & NLP | E14: =_xlfn.XLOOKUP(A14,Skill_Matching!$A$2:$A$200,Skill_Matching!$D$2:$D$200,"") -> 34.62 | F14: =IF(B14="Covered",1,0) -> 1 | G14: =IF(OR(B14="Covered",B14="Partially Covered"),1,0) -> 1
A15: {=IFERROR(INDEX(Skill_Matching!$A$2:$A$200,_xlfn.AGGREGATE(15,6,(ROW(Skill_Matching!$A$2:$A$200)-ROW(Skill_Matching!$A$2)+1)/(Skill_Matching!$D$2:$D$200<>""),ROWS($A$5:A15))),"")} -> PyTorch | B15: {=IF(A15="","",INDEX(Skill_Matching!$H$2:$H$200,_xlfn.AGGREGATE(15,6,(ROW(Skill_Matching!$A$2:$A$200)-ROW(Skill_Matching!$A$2)+1)/(Skill_Matching!$D$2:$D$200<>""),ROWS($A$5:A15))))} -> Partially Covered | C15: =IF(E15="","",IF(E15>=50,"Tier 1",IF(E15>=25,"Tier 2",IF(E15>=10,"Tier 3","Tier 4")))) -> Tier 2 | D15: =_xlfn.XLOOKUP(A15,Skill_Matching!$A$2:$A$200,Skill_Matching!$J$2:$J$200,"") -> Deep Learning | E15: =_xlfn.XLOOKUP(A15,Skill_Matching!$A$2:$A$200,Skill_Matching!$D$2:$D$200,"") -> 33.85 | F15: =IF(B15="Covered",1,0) -> 0 | G15: =IF(OR(B15="Covered",B15="Partially Covered"),1,0) -> 1
A16: {=IFERROR(INDEX(Skill_Matching!$A$2:$A$200,_xlfn.AGGREGATE(15,6,(ROW(Skill_Matching!$A$2:$A$200)-ROW(Skill_Matching!$A$2)+1)/(Skill_Matching!$D$2:$D$200<>""),ROWS($A$5:A16))),"")} -> TensorFlow / Keras | B16: {=IF(A16="","",INDEX(Skill_Matching!$H$2:$H$200,_xlfn.AGGREGATE(15,6,(ROW(Skill_Matching!$A$2:$A$200)-ROW(Skill_Matching!$A$2)+1)/(Skill_Matching!$D$2:$D$200<>""),ROWS($A$5:A16))))} -> Partially Covered | C16: =IF(E16="","",IF(E16>=50,"Tier 1",IF(E16>=25,"Tier 2",IF(E16>=10,"Tier 3","Tier 4")))) -> Tier 2 | D16: =_xlfn.XLOOKUP(A16,Skill_Matching!$A$2:$A$200,Skill_Matching!$J$2:$J$200,"") -> Deep Learning | E16: =_xlfn.XLOOKUP(A16,Skill_Matching!$A$2:$A$200,Skill_Matching!$D$2:$D$200,"") -> 32.31 | F16: =IF(B16="Covered",1,0) -> 0 | G16: =IF(OR(B16="Covered",B16="Partially Covered"),1,0) -> 1
... A85: {=IFERROR(INDEX(Skill_Matching!$A$2:$A$200,_xlfn.AGGREGATE(15,6,(ROW(Skill_Matching!$A$2:$A$200)-ROW(Skill_Matching!$A$2)+1)/(Skill_Matching!$D$2:$D$200<>""),ROWS($A$5:A85))),"")} -> Browser Automation | B85: {=IF(A85="","",INDEX(Skill_Matching!$H$2:$H$200,_xlfn.AGGREGATE(15,6,(ROW(Skill_Matching!$A$2:$A$200)-ROW(Skill_Matching!$A$2)+1)/(Skill_Matching!$D$2:$D$200<>""),ROWS($A$5:A85))))} -> Industry Only | C85: =IF(E85="","",IF(E85>=50,"Tier 1",IF(E85>=25,"Tier 2",IF(E85>=10,"Tier 3","Tier 4")))) -> Tier 4 | D85: =_xlfn.XLOOKUP(A85,Skill_Matching!$A$2:$A$200,Skill_Matching!$J$2:$J$200,"") -> Software Engineering | E85: =_xlfn.XLOOKUP(A85,Skill_Matching!$A$2:$A$200,Skill_Matching!$D$2:$D$200,"") -> 0.77 | F85: =IF(B85="Covered",1,0) -> 0 | G85: =IF(OR(B85="Covered",B85="Partially Covered"),1,0) -> 0
A86: {=IFERROR(INDEX(Skill_Matching!$A$2:$A$200,_xlfn.AGGREGATE(15,6,(ROW(Skill_Matching!$A$2:$A$200)-ROW(Skill_Matching!$A$2)+1)/(Skill_Matching!$D$2:$D$200<>""),ROWS($A$5:A86))),"")} | B86: {=IF(A86="","",INDEX(Skill_Matching!$H$2:$H$200,_xlfn.AGGREGATE(15,6,(ROW(Skill_Matching!$A$2:$A$200)-ROW(Skill_Matching!$A$2)+1)/(Skill_Matching!$D$2:$D$200<>""),ROWS($A$5:A86))))}
A87: {=IFERROR(INDEX(Skill_Matching!$A$2:$A$200,_xlfn.AGGREGATE(15,6,(ROW(Skill_Matching!$A$2:$A$200)-ROW(Skill_Matching!$A$2)+1)/(Skill_Matching!$D$2:$D$200<>""),ROWS($A$5:A87))),"")} | B87: {=IF(A87="","",INDEX(Skill_Matching!$H$2:$H$200,_xlfn.AGGREGATE(15,6,(ROW(Skill_Matching!$A$2:$A$200)-ROW(Skill_Matching!$A$2)+1)/(Skill_Matching!$D$2:$D$200<>""),ROWS($A$5:A87))))}
A88: {=IFERROR(INDEX(Skill_Matching!$A$2:$A$200,_xlfn.AGGREGATE(15,6,(ROW(Skill_Matching!$A$2:$A$200)-ROW(Skill_Matching!$A$2)+1)/(Skill_Matching!$D$2:$D$200<>""),ROWS($A$5:A88))),"")}
A89: {=IFERROR(INDEX(Skill_Matching!$A$2:$A$200,_xlfn.AGGREGATE(15,6,(ROW(Skill_Matching!$A$2:$A$200)-ROW(Skill_Matching!$A$2)+1)/(Skill_Matching!$D$2:$D$200<>""),ROWS($A$5:A89))),"")}
